Workbook

Sheet Assumptions
A1: ROAST LAUNCH
A2: KEY ASSUMPTIONS & INPUT PARAMETERS
A4: CUSTOMER VOLUME & GROWTH
A5: Starting Daily Customers (Month 1) | B5: 100 | C5: Conservative ramp-up
A6: Target Daily Customers (Month 10+) | B6: 220 | C6: Mature shop capacity
A7: Monthly Customer Growth Rate | B7: 0.055 | C7: 5.5% month-over-month
A9: REVENUE ASSUMPTIONS
A10: Average Ticket Price | B10: 7.5 | C10: Coffee + pastry/food
A11: Days Open Per Month | B11: 22 | C11: Closed 2 Sundays + holidays
A13: COST OF GOODS SOLD (% of Revenue)
A14: Coffee & Tea | B14: 0.09
A15: Milk & Dairy | B15: 0.06
A16: Food Items | B16: 0.25
A17: Cups & Supplies | B17: 0.03
A19: MONTHLY OPERATING EXPENSES (Fixed)
A20: Rent | B20: 5000 | C20: Prime location, ~1200 sq ft
A21: Utilities | B21: 450 | C21: Electric, gas, water
A22: Payroll | B22: 11500 | C22: 3-4 staff: manager + baristas
A23: Payroll Taxes % | B23: 0.13 | C23: FICA, unemployment, workers comp
A24: Marketing | B24: 800 | C24: Social media, local ads
A25: Insurance | B25: 600 | C25: Business & liability
A26: Supplies & Maintenance | B26: 400 | C26: Cleaning, repairs
A27: POS & Technology | B27: 300 | C27: System, software, WiFi
A28: Accounting & Professional | B28: 250 | C28: Bookkeeping, accountant
A29: Miscellaneous | B29: 300 | C29: Contingency
A31: Tax Rate (% of Profit) | B31: 0.25 | C31: Federal + state combined

Sheet Startup Costs
A1: ROAST LAUNCH
A2: STARTUP COSTS & ONE-TIME INVESTMENTS
A4: REAL ESTATE & BUILD-OUT
A5: Security Deposit (2 months rent) | B5: 10000
A6: Leasehold Improvements | B6: 35000
A7: Furniture & Fixtures | B7: 8000
A8: REAL ESTATE & BUILD-OUT SUBTOTAL | B8: =SUM(B5:B7) -> 53000
A10: EQUIPMENT
A11: Espresso Machine (2-group commercial) | B11: 6500
A12: Coffee Grinders | B12: 3500
A13: Brewers & Pour-Over Equipment | B13: 2000
A14: Refrigeration & Display | B14: 4500
A15: Sinks & Water Systems | B15: 2000
A16: EQUIPMENT SUBTOTAL | B16: =SUM(B11:B15) -> 18500
A18: TECHNOLOGY & POS
A19: POS System & Hardware | B19: 2500
A20: Printers & Peripherals | B20: 800
A21: Internet & WiFi | B21: 500
A22: TECHNOLOGY & POS SUBTOTAL | B22: =SUM(B19:B21) -> 3800
A24: INITIAL INVENTORY
A25: Coffee Beans & Tea | B25: 3500
A26: Milk & Dairy Products | B26: 1200
A27: Food Items (pastries, etc) | B27: 2500
A28: Cups, Lids, Straws, Napkins | B28: 1800
A29: Syrups, Toppings, Supplies | B29: 800
A30: INITIAL INVENTORY SUBTOTAL | B30: =SUM(B25:B29) -> 9800
A32: BRANDING & MARKETING
A33: Logo & Brand Design | B33: 1500
A34: Signage & Exterior Branding | B34: 3000
A35: Website Development | B35: 2500
A36: Initial Marketing Campaign | B36: 2500
A37: BRANDING & MARKETING SUBTOTAL | B37: =SUM(B33:B36) -> 9500
A39: LEGAL & ADMINISTRATIVE
A40: Business Formation & LLC | B40: 800
A41: Permits & Licenses | B41: 2000
A42: Insurance Deposit (3 months) | B42: 1800
A43: LEGAL & ADMINISTRATIVE SUBTOTAL | B43: =SUM(B40:B42) -> 4600
A45: WORKING CAPITAL RESERVE
A46: Operating Reserve (3 months cover) | B46: 25000
A47: WORKING CAPITAL RESERVE SUBTOTAL | B47: =SUM(B46) -> 25000
...

Sheet Monthly P&L
A1: ROAST LAUNCH
A2: 24-MONTH PROFIT & LOSS PROJECTION
A3: MONTH | B3: M1 | C3: M2 | D3: M3 | E3: M4 | F3: M5 | G3: M6 | H3: M7 | I3: M8 | J3: M9 | K3: M10 | L3: M11 | M3: M12 | N3: Y2M1 | O3: Y2M2 | P3: Y2M3 | Q3: Y2M4 | R3: Y2M5 | S3: Y2M6 | T3: Y2M7 | U3: Y2M8 | V3: Y2M9 | W3: Y2M10 | X3: Y2M11 | Y3: Y2M12
A4: Daily Customers | B4: =Assumptions!B5 -> 100 | C4: =MIN(B4*(1+Assumptions!B7), Assumptions!B6) -> 105.5 | D4: =MIN(C4*(1+Assumptions!B7), Assumptions!B6) -> 111.3025 | E4: =MIN(D4*(1+Assumptions!B7), Assumptions!B6) -> 117.42414 | F4: =MIN(E4*(1+Assumptions!B7), Assumptions!B6) -> 123.88247 | G4: =MIN(F4*(1+Assumptions!B7), Assumptions!B6) -> 130.696 | H4: =MIN(G4*(1+Assumptions!B7), Assumptions!B6) -> 137.88428 | I4: =MIN(H4*(1+Assumptions!B7), Assumptions!B6) -> 145.46792 | J4: =MIN(I4*(1+Assumptions!B7), Assumptions!B6) -> 153.46865 | K4: =MIN(J4*(1+Assumptions!B7), Assumptions!B6) -> 161.90943 | L4: =MIN(K4*(1+Assumptions!B7), Assumptions!B6) -> 170.81445 | M4: =MIN(L4*(1+Assumptions!B7), Assumptions!B6) -> 180.20924 | N4: =MIN(M4*(1+Assumptions!B7), Assumptions!B6) -> 190.12075 | O4: =MIN(N4*(1+Assumptions!B7), Assumptions!B6) -> 200.57739 | P4: =MIN(O4*(1+Assumptions!B7), Assumptions!B6) -> 211.60915 | Q4: =MIN(P4*(1+Assumptions!B7), Assumptions!B6) -> 220 | R4: =MIN(Q4*(1+Assumptions!B7), Assumptions!B6) -> 220 | S4: =MIN(R4*(1+Assumptions!B7), Assumptions!B6) -> 220 | T4: =MIN(S4*(1+Assumptions!B7), Assumptions!B6) -> 220 | U4: =MIN(T4*(1+Assumptions!B7), Assumptions!B6) -> 220 | V4: =MIN(U4*(1+Assumptions!B7), Assumptions!B6) -> 220 | W4: =MIN(V4*(1+Assumptions!B7), Assumptions!B6) -> 220 | X4: =MIN(W4*(1+Assumptions!B7), Assumptions!B6) -> 220 | Y4: =MIN(X4*(1+Assumptions!B7), Assumptions!B6) -> 220
A5: Days Open | B5: =Assumptions!B11 -> 22 | C5: =Assumptions!B11 -> 22 | D5: =Assumptions!B11 -> 22 | E5: =Assumptions!B11 -> 22 | F5: =Assumptions!B11 -> 22 | G5: =Assumptions!B11 -> 22 | H5: =Assumptions!B11 -> 22 | I5: =Assumptions!B11 -> 22 | J5: =Assumptions!B11 -> 22 | K5: =Assumptions!B11 -> 22 | L5: =Assumptions!B11 -> 22 | M5: =Assumptions!B11 -> 22 | N5: =Assumptions!B11 -> 22 | O5: =Assumptions!B11 -> 22 | P5: =Assumptions!B11 -> 22 | Q5: =Assumptions!B11 -> 22 | R5: =Assumptions!B11 -> 22 | S5: =Assumptions!B11 -> 22 | T5: =Assumptions!B11 -> 22 | U5: =Assumptions!B11 -> 22 | V5: =Assumptions!B11 -> 22 | W5: =Assumptions!B11 -> 22 | X5: =Assumptions!B11 -> 22 | Y5: =Assumptions!B11 -> 22
A6: Avg Ticket Price | B6: =Assumptions!B10 -> 7.5 | C6: =Assumptions!B10 -> 7.5 | D6: =Assumptions!B10 -> 7.5 | E6: =Assumptions!B10 -> 7.5 | F6: =Assumptions!B10 -> 7.5 | G6: =Assumptions!B10 -> 7.5 | H6: =Assumptions!B10 -> 7.5 | I6: =Assumptions!B10 -> 7.5 | J6: =Assumptions!B10 -> 7.5 | K6: =Assumptions!B10 -> 7.5 | L6: =Assumptions!B10 -> 7.5 | M6: =Assumptions!B10 -> 7.5 | N6: =Assumptions!B10 -> 7.5 | O6: =Assumptions!B10 -> 7.5 | P6: =Assumptions!B10 -> 7.5 | Q6: =Assumptions!B10 -> 7.5 | R6: =Assumptions!B10 -> 7.5 | S6: =Assumptions!B10 -> 7.5 | T6: =Assumptions!B10 -> 7.5 | U6: =Assumptions!B10 -> 7.5 | V6: =Assumptions!B10 -> 7.5 | W6: =Assumptions!B10 -> 7.5 | X6: =Assumptions!B10 -> 7.5 | Y6: =Assumptions!B10 -> 7.5
A8: REVENUE
A9: Total Revenue | B9: =B4*B5*B6 -> 16500 | C9: =C4*C5*C6 -> 17407.5 | D9: =D4*D5*D6 -> 18364.912 | E9: =E4*E5*E6 -> 19374.983 | F9: =F4*F5*F6 -> 20440.607 | G9: =G4*G5*G6 -> 21564.84 | H9: =H4*H5*H6 -> 22750.906 | I9: =I4*I5*I6 -> 24002.206 | ... Y9: =Y4*Y5*Y6 -> 36300
A11: COST OF GOODS SOLD
A12: Coffee & Tea | B12: =B9*Assumptions!B14 -> 1485 | C12: =C9*Assumptions!B14 -> 1566.675 | D12: =D9*Assumptions!B14 -> 1652.8421 | E12: =E9*Assumptions!B14 -> 1743.7484 | F12: =F9*Assumptions!B14 -> 1839.6546 | G12: =G9*Assumptions!B14 -> 1940.8356 | H12: =H9*Assumptions!B14 -> 2047.5816 | I12: =I9*Assumptions!B14 -> 2160.1986 | J12: =J9*Assumptions!B14 -> 2279.0095 | K12: =K9*Assumptions!B14 -> 2404.355 | L12: =L9*Assumptions!B14 -> 2536.5945 | M12: =M9*Assumptions!B14 -> 2676.1072 | N12: =N9*Assumptions!B14 -> 2823.2931 | O12: =O9*Assumptions!B14 -> 2978.5742 | P12: =P9*Assumptions!B14 -> 3142.3958 | Q12: =Q9*Assumptions!B14 -> 3267 | R12: =R9*Assumptions!B14 -> 3267 | S12: =S9*Assumptions!B14 -> 3267 | T12: =T9*Assumptions!B14 -> 3267 | U12: =U9*Assumptions!B14 -> 3267 | V12: =V9*Assumptions!B14 -> 3267 | W12: =W9*Assumptions!B14 -> 3267 | X12: =X9*Assumptions!B14 -> 3267 | Y12: =Y9*Assumptions!B14 -> 3267
A13: Milk & Dairy | B13: =B9*Assumptions!B15 -> 990 | C13: =C9*Assumptions!B15 -> 1044.45 | D13: =D9*Assumptions!B15 -> 1101.8947 | E13: =E9*Assumptions!B15 -> 1162.499 | F13: =F9*Assumptions!B15 -> 1226.4364 | G13: =G9*Assumptions!B15 -> 1293.8904 | H13: =H9*Assumptions!B15 -> 1365.0544 | I13: =I9*Assumptions!B15 -> 1440.1324 | J13: =J9*Assumptions!B15 -> 1519.3396 | K13: =K9*Assumptions!B15 -> 1602.9033 | L13: =L9*Assumptions!B15 -> 1691.063 | M13: =M9*Assumptions!B15 -> 1784.0715 | N13: =N9*Assumptions!B15 -> 1882.1954 | O13: =O9*Assumptions!B15 -> 1985.7162 | P13: =P9*Assumptions!B15 -> 2094.9305 | Q13: =Q9*Assumptions!B15 -> 2178 | R13: =R9*Assumptions!B15 -> 2178 | S13: =S9*Assumptions!B15 -> 2178 | T13: =T9*Assumptions!B15 -> 2178 | U13: =U9*Assumptions!B15 -> 2178 | V13: =V9*Assumptions!B15 -> 2178 | W13: =W9*Assumptions!B15 -> 2178 | X13: =X9*Assumptions!B15 -> 2178 | Y13: =Y9*Assumptions!B15 -> 2178
A14: Food Items | B14: =B9*Assumptions!B16 -> 4125 | C14: =C9*Assumptions!B16 -> 4351.875 | D14: =D9*Assumptions!B16 -> 4591.2281 | E14: =E9*Assumptions!B16 -> 4843.7457 | F14: =F9*Assumptions!B16 -> 5110.1517 | G14: =G9*Assumptions!B16 -> 5391.21 | H14: =H9*Assumptions!B16 -> 5687.7266 | I14: =I9*Assumptions!B16 -> 6000.5515 | J14: =J9*Assumptions!B16 -> 6330.5819 | K14: =K9*Assumptions!B16 -> 6678.7639 | L14: =L9*Assumptions!B16 -> 7046.0959 | M14: =M9*Assumptions!B16 -> 7433.6312 | N14: =N9*Assumptions!B16 -> 7842.4809 | O14: =O9*Assumptions!B16 -> 8273.8173 | P14: =P9*Assumptions!B16 -> 8728.8773 | Q14: =Q9*Assumptions!B16 -> 9075 | R14: =R9*Assumptions!B16 -> 9075 | S14: =S9*Assumptions!B16 -> 9075 | T14: =T9*Assumptions!B16 -> 9075 | U14: =U9*Assumptions!B16 -> 9075 | V14: =V9*Assumptions!B16 -> 9075 | W14: =W9*Assumptions!B16 -> 9075 | X14: =X9*Assumptions!B16 -> 9075 | Y14: =Y9*Assumptions!B16 -> 9075
A15: Cups & Supplies | B15: =B9*Assumptions!B17 -> 495 | C15: =C9*Assumptions!B17 -> 522.225 | D15: =D9*Assumptions!B17 -> 550.94737 | E15: =E9*Assumptions!B17 -> 581.24948 | F15: =F9*Assumptions!B17 -> 613.2182 | G15: =G9*Assumptions!B17 -> 646.9452 | H15: =H9*Assumptions!B17 -> 682.52719 | I15: =I9*Assumptions!B17 -> 720.06618 | J15: =J9*Assumptions!B17 -> 759.66982 | K15: =K9*Assumptions!B17 -> 801.45167 | L15: =L9*Assumptions!B17 -> 845.53151 | M15: =M9*Assumptions!B17 -> 892.03574 | N15: =N9*Assumptions!B17 -> 941.09771 | O15: =O9*Assumptions!B17 -> 992.85808 | P15: =P9*Assumptions!B17 -> 1047.4653 | Q15: =Q9*Assumptions!B17 -> 1089 | R15: =R9*Assumptions!B17 -> 1089 | S15: =S9*Assumptions!B17 -> 1089 | T15: =T9*Assumptions!B17 -> 1089 | U15: =U9*Assumptions!B17 -> 1089 | V15: =V9*Assumptions!B17 -> 1089 | W15: =W9*Assumptions!B17 -> 1089 | X15: =X9*Assumptions!B17 -> 1089 | Y15: =Y9*Assumptions!B17 -> 1089
A16: Total COGS | B16: =SUM(B12:B15) -> 7095 | C16: =SUM(C12:C15) -> 7485.225 | D16: =SUM(D12:D15) -> 7896.9124 | E16: =SUM(E12:E15) -> 8331.2426 | F16: =SUM(F12:F15) -> 8789.4609 | G16: =SUM(G12:G15) -> 9272.8812 | H16: =SUM(H12:H15) -> 9782.8897 | I16: =SUM(I12:I15) -> 10320.949 | ... Y16: =SUM(Y12:Y15) -> 15609
A17: GROSS PROFIT | B17: =B9-B16 -> 9405 | C17: =C9-C16 -> 9922.275 | D17: =D9-D16 -> 10468 | E17: =E9-E16 -> 11043.74 | F17: =F9-F16 -> 11651.146 | G17: =G9-G16 -> 12291.959 | H17: =H9-H16 -> 12968.017 | I17: =I9-I16 -> 13681.258 | ... Y17: =Y9-Y16 -> 20691
A19: OPERATING EXPENSES
A20: Rent | B20: =Assumptions!B20 -> 5000 | C20: =Assumptions!B20 -> 5000 | D20: =Assumptions!B20 -> 5000 | E20: =Assumptions!B20 -> 5000 | F20: =Assumptions!B20 -> 5000 | G20: =Assumptions!B20 -> 5000 | H20: =Assumptions!B20 -> 5000 | I20: =Assumptions!B20 -> 5000 | J20: =Assumptions!B20 -> 5000 | K20: =Assumptions!B20 -> 5000 | L20: =Assumptions!B20 -> 5000 | M20: =Assumptions!B20 -> 5000 | N20: =Assumptions!B20 -> 5000 | O20: =Assumptions!B20 -> 5000 | P20: =Assumptions!B20 -> 5000 | Q20: =Assumptions!B20 -> 5000 | R20: =Assumptions!B20 -> 5000 | S20: =Assumptions!B20 -> 5000 | T20: =Assumptions!B20 -> 5000 | U20: =Assumptions!B20 -> 5000 | V20: =Assumptions!B20 -> 5000 | W20: =Assumptions!B20 -> 5000 | X20: =Assumptions!B20 -> 5000 | Y20: =Assumptions!B20 -> 5000
A21: Utilities | B21: =Assumptions!B21 -> 450 | C21: =Assumptions!B21 -> 450 | D21: =Assumptions!B21 -> 450 | E21: =Assumptions!B21 -> 450 | F21: =Assumptions!B21 -> 450 | G21: =Assumptions!B21 -> 450 | H21: =Assumptions!B21 -> 450 | I21: =Assumptions!B21 -> 450 | J21: =Assumptions!B21 -> 450 | K21: =Assumptions!B21 -> 450 | L21: =Assumptions!B21 -> 450 | M21: =Assumptions!B21 -> 450 | N21: =Assumptions!B21 -> 450 | O21: =Assumptions!B21 -> 450 | P21: =Assumptions!B21 -> 450 | Q21: =Assumptions!B21 -> 450 | R21: =Assumptions!B21 -> 450 | S21: =Assumptions!B21 -> 450 | T21: =Assumptions!B21 -> 450 | U21: =Assumptions!B21 -> 450 | V21: =Assumptions!B21 -> 450 | W21: =Assumptions!B21 -> 450 | X21: =Assumptions!B21 -> 450 | Y21: =Assumptions!B21 -> 450
A22: Payroll | B22: =Assumptions!B22 -> 11500 | C22: =Assumptions!B22 -> 11500 | D22: =Assumptions!B22 -> 11500 | E22: =Assumptions!B22 -> 11500 | F22: =Assumptions!B22 -> 11500 | G22: =Assumptions!B22 -> 11500 | H22: =Assumptions!B22 -> 11500 | I22: =Assumptions!B22 -> 11500 | J22: =Assumptions!B22 -> 11500 | K22: =Assumptions!B22 -> 11500 | L22: =Assumptions!B22 -> 11500 | M22: =Assumptions!B22 -> 11500 | N22: =Assumptions!B22 -> 11500 | O22: =Assumptions!B22 -> 11500 | P22: =Assumptions!B22 -> 11500 | Q22: =Assumptions!B22 -> 11500 | R22: =Assumptions!B22 -> 11500 | S22: =Assumptions!B22 -> 11500 | T22: =Assumptions!B22 -> 11500 | U22: =Assumptions!B22 -> 11500 | V22: =Assumptions!B22 -> 11500 | W22: =Assumptions!B22 -> 11500 | X22: =Assumptions!B22 -> 11500 | Y22: =Assumptions!B22 -> 11500
A23: Payroll Taxes | B23: =B22*Assumptions!B23 -> 1495 | C23: =C22*Assumptions!B23 -> 1495 | D23: =D22*Assumptions!B23 -> 1495 | E23: =E22*Assumptions!B23 -> 1495 | F23: =F22*Assumptions!B23 -> 1495 | G23: =G22*Assumptions!B23 -> 1495 | H23: =H22*Assumptions!B23 -> 1495 | I23: =I22*Assumptions!B23 -> 1495 | J23: =J22*Assumptions!B23 -> 1495 | K23: =K22*Assumptions!B23 -> 1495 | L23: =L22*Assumptions!B23 -> 1495 | M23: =M22*Assumptions!B23 -> 1495 | N23: =N22*Assumptions!B23 -> 1495 | O23: =O22*Assumptions!B23 -> 1495 | P23: =P22*Assumptions!B23 -> 1495 | Q23: =Q22*Assumptions!B23 -> 1495 | R23: =R22*Assumptions!B23 -> 1495 | S23: =S22*Assumptions!B23 -> 1495 | T23: =T22*Assumptions!B23 -> 1495 | U23: =U22*Assumptions!B23 -> 1495 | V23: =V22*Assumptions!B23 -> 1495 | W23: =W22*Assumptions!B23 -> 1495 | X23: =X22*Assumptions!B23 -> 1495 | Y23: =Y22*Assumptions!B23 -> 1495
A24: Marketing | B24: =Assumptions!B24 -> 800 | C24: =Assumptions!B24 -> 800 | D24: =Assumptions!B24 -> 800 | E24: =Assumptions!B24 -> 800 | F24: =Assumptions!B24 -> 800 | G24: =Assumptions!B24 -> 800 | H24: =Assumptions!B24 -> 800 | I24: =Assumptions!B24 -> 800 | J24: =Assumptions!B24 -> 800 | K24: =Assumptions!B24 -> 800 | L24: =Assumptions!B24 -> 800 | M24: =Assumptions!B24 -> 800 | N24: =Assumptions!B24 -> 800 | O24: =Assumptions!B24 -> 800 | P24: =Assumptions!B24 -> 800 | Q24: =Assumptions!B24 -> 800 | R24: =Assumptions!B24 -> 800 | S24: =Assumptions!B24 -> 800 | T24: =Assumptions!B24 -> 800 | U24: =Assumptions!B24 -> 800 | V24: =Assumptions!B24 -> 800 | W24: =Assumptions!B24 -> 800 | X24: =Assumptions!B24 -> 800 | Y24: =Assumptions!B24 -> 800
A25: Insurance | B25: =Assumptions!B25 -> 600 | C25: =Assumptions!B25 -> 600 | D25: =Assumptions!B25 -> 600 | E25: =Assumptions!B25 -> 600 | F25: =Assumptions!B25 -> 600 | G25: =Assumptions!B25 -> 600 | H25: =Assumptions!B25 -> 600 | I25: =Assumptions!B25 -> 600 | J25: =Assumptions!B25 -> 600 | K25: =Assumptions!B25 -> 600 | L25: =Assumptions!B25 -> 600 | M25: =Assumptions!B25 -> 600 | N25: =Assumptions!B25 -> 600 | O25: =Assumptions!B25 -> 600 | P25: =Assumptions!B25 -> 600 | Q25: =Assumptions!B25 -> 600 | R25: =Assumptions!B25 -> 600 | S25: =Assumptions!B25 -> 600 | T25: =Assumptions!B25 -> 600 | U25: =Assumptions!B25 -> 600 | V25: =Assumptions!B25 -> 600 | W25: =Assumptions!B25 -> 600 | X25: =Assumptions!B25 -> 600 | Y25: =Assumptions!B25 -> 600
A26: Supplies & Maintenance | B26: =Assumptions!B26 -> 400 | C26: =Assumptions!B26 -> 400 | D26: =Assumptions!B26 -> 400 | E26: =Assumptions!B26 -> 400 | F26: =Assumptions!B26 -> 400 | G26: =Assumptions!B26 -> 400 | H26: =Assumptions!B26 -> 400 | I26: =Assumptions!B26 -> 400 | J26: =Assumptions!B26 -> 400 | K26: =Assumptions!B26 -> 400 | L26: =Assumptions!B26 -> 400 | M26: =Assumptions!B26 -> 400 | N26: =Assumptions!B26 -> 400 | O26: =Assumptions!B26 -> 400 | P26: =Assumptions!B26 -> 400 | Q26: =Assumptions!B26 -> 400 | R26: =Assumptions!B26 -> 400 | S26: =Assumptions!B26 -> 400 | T26: =Assumptions!B26 -> 400 | U26: =Assumptions!B26 -> 400 | V26: =Assumptions!B26 -> 400 | W26: =Assumptions!B26 -> 400 | X26: =Assumptions!B26 -> 400 | Y26: =Assumptions!B26 -> 400
A27: POS & Technology | B27: =Assumptions!B27 -> 300 | C27: =Assumptions!B27 -> 300 | D27: =Assumptions!B27 -> 300 | E27: =Assumptions!B27 -> 300 | F27: =Assumptions!B27 -> 300 | G27: =Assumptions!B27 -> 300 | H27: =Assumptions!B27 -> 300 | I27: =Assumptions!B27 -> 300 | J27: =Assumptions!B27 -> 300 | K27: =Assumptions!B27 -> 300 | L27: =Assumptions!B27 -> 300 | M27: =Assumptions!B27 -> 300 | N27: =Assumptions!B27 -> 300 | O27: =Assumptions!B27 -> 300 | P27: =Assumptions!B27 -> 300 | Q27: =Assumptions!B27 -> 300 | R27: =Assumptions!B27 -> 300 | S27: =Assumptions!B27 -> 300 | T27: =Assumptions!B27 -> 300 | U27: =Assumptions!B27 -> 300 | V27: =Assumptions!B27 -> 300 | W27: =Assumptions!B27 -> 300 | X27: =Assumptions!B27 -> 300 | Y27: =Assumptions!B27 -> 300
A28: Accounting & Professional | B28: =Assumptions!B28 -> 250 | C28: =Assumptions!B28 -> 250 | D28: =Assumptions!B28 -> 250 | E28: =Assumptions!B28 -> 250 | F28: =Assumptions!B28 -> 250 | G28: =Assumptions!B28 -> 250 | H28: =Assumptions!B28 -> 250 | I28: =Assumptions!B28 -> 250 | J28: =Assumptions!B28 -> 250 | K28: =Assumptions!B28 -> 250 | L28: =Assumptions!B28 -> 250 | M28: =Assumptions!B28 -> 250 | N28: =Assumptions!B28 -> 250 | O28: =Assumptions!B28 -> 250 | P28: =Assumptions!B28 -> 250 | Q28: =Assumptions!B28 -> 250 | R28: =Assumptions!B28 -> 250 | S28: =Assumptions!B28 -> 250 | T28: =Assumptions!B28 -> 250 | U28: =Assumptions!B28 -> 250 | V28: =Assumptions!B28 -> 250 | W28: =Assumptions!B28 -> 250 | X28: =Assumptions!B28 -> 250 | Y28: =Assumptions!B28 -> 250
A29: Miscellaneous | B29: =Assumptions!B29 -> 300 | C29: =Assumptions!B29 -> 300 | D29: =Assumptions!B29 -> 300 | E29: =Assumptions!B29 -> 300 | F29: =Assumptions!B29 -> 300 | G29: =Assumptions!B29 -> 300 | H29: =Assumptions!B29 -> 300 | I29: =Assumptions!B29 -> 300 | J29: =Assumptions!B29 -> 300 | K29: =Assumptions!B29 -> 300 | L29: =Assumptions!B29 -> 300 | M29: =Assumptions!B29 -> 300 | N29: =Assumptions!B29 -> 300 | O29: =Assumptions!B29 -> 300 | P29: =Assumptions!B29 -> 300 | Q29: =Assumptions!B29 -> 300 | R29: =Assumptions!B29 -> 300 | S29: =Assumptions!B29 -> 300 | T29: =Assumptions!B29 -> 300 | U29: =Assumptions!B29 -> 300 | V29: =Assumptions!B29 -> 300 | W29: =Assumptions!B29 -> 300 | X29: =Assumptions!B29 -> 300 | Y29: =Assumptions!B29 -> 300
A30: Total Operating Expenses | B30: =SUM(B20:B29) -> 21095 | C30: =SUM(C20:C29) -> 21095 | D30: =SUM(D20:D29) -> 21095 | E30: =SUM(E20:E29) -> 21095 | F30: =SUM(F20:F29) -> 21095 | G30: =SUM(G20:G29) -> 21095 | H30: =SUM(H20:H29) -> 21095 | I30: =SUM(I20:I29) -> 21095 | ... Y30: =SUM(Y20:Y29) -> 21095
A32: EBITDA | B32: =B17-B30 -> -11690 | C32: =C17-C30 -> -11172.725 | D32: =D17-D30 -> -10627 | E32: =E17-E30 -> -10051.26 | F32: =F17-F30 -> -9443.8542 | G32: =G17-G30 -> -8803.0411 | H32: =H17-H30 -> -8126.9834 | I32: =I17-I30 -> -7413.7425 | ... Y32: =Y17-Y30 -> -404
A33: Taxes (25% of profit if positive) | B33: =IF(B32>0, B32*Assumptions!B31, 0) -> 0 | C33: =IF(C32>0, C32*Assumptions!B31, 0) -> 0 | D33: =IF(D32>0, D32*Assumptions!B31, 0) -> 0 | E33: =IF(E32>0, E32*Assumptions!B31, 0) -> 0 | F33: =IF(F32>0, F32*Assumptions!B31, 0) -> 0 | G33: =IF(G32>0, G32*Assumptions!B31, 0) -> 0 | H33: =IF(H32>0, H32*Assumptions!B31, 0) -> 0 | I33: =IF(I32>0, I32*Assumptions!B31, 0) -> 0 | J33: =IF(J32>0, J32*Assumptions!B31, 0) -> 0 | K33: =IF(K32>0, K32*Assumptions!B31, 0) -> 0 | L33: =IF(L32>0, L32*Assumptions!B31, 0) -> 0 | M33: =IF(M32>0, M32*Assumptions!B31, 0) -> 0 | N33: =IF(N32>0, N32*Assumptions!B31, 0) -> 0 | O33: =IF(O32>0, O32*Assumptions!B31, 0) -> 0 | P33: =IF(P32>0, P32*Assumptions!B31, 0) -> 0 | Q33: =IF(Q32>0, Q32*Assumptions!B31, 0) -> 0 | R33: =IF(R32>0, R32*Assumptions!B31, 0) -> 0 | S33: =IF(S32>0, S32*Assumptions!B31, 0) -> 0 | T33: =IF(T32>0, T32*Assumptions!B31, 0) -> 0 | U33: =IF(U32>0, U32*Assumptions!B31, 0) -> 0 | V33: =IF(V32>0, V32*Assumptions!B31, 0) -> 0 | W33: =IF(W32>0, W32*Assumptions!B31, 0) -> 0 | X33: =IF(X32>0, X32*Assumptions!B31, 0) -> 0 | Y33: =IF(Y32>0, Y32*Assumptions!B31, 0) -> 0
A35: NET INCOME / LOSS | B35: =B32-B33 -> -11690 | C35: =C32-C33 -> -11172.725 | D35: =D32-D33 -> -10627 | E35: =E32-E33 -> -10051.26 | F35: =F32-F33 -> -9443.8542 | G35: =G32-G33 -> -8803.0411 | H35: =H32-H33 -> -8126.9834 | I35: =I32-I33 -> -7413.7425 | ... Y35: =Y32-Y33 -> -404
A36: CUMULATIVE NET INCOME | B36: =B35 -> -11690 | C36: =B36+C35 -> -22862.725 | D36: =C36+D35 -> -33489.725 | E36: =D36+E35 -> -43540.985 | F36: =E36+F35 -> -52984.839 | G36: =F36+G35 -> -61787.88 | H36: =G36+H35 -> -69914.863 | I36: =H36+I35 -> -77328.606 | J36: =I36+J35 -> -83989.879 | ... Y36: =X36+Y35 -> -109307.52

Sheet Dashboard
A1: ROAST LAUNCH
A2: EXECUTIVE DASHBOARD
A4: KEY METRICS
A5: Total Startup Investment | B5: ='Startup Costs'!B49 -> 124200
A6: Year 1 Total Revenue | B6: =SUM('Monthly P&L'!B9:M9) -> 270362.25
A7: Year 1 Net Income/(Loss) | B7: =SUM('Monthly P&L'!B35:M35) -> -99033.52
A8: Months to Profitability | B8: =IFERROR(MATCH(TRUE(), 'Monthly P&L'!B35:M35>0, 0), "Not yet") -> Not yet
A9: Year 2 Projected Net Income | B9: =SUM('Monthly P&L'!N35:Y35) -> -10274
A10: Avg Monthly Revenue (M1-3) | B10: =AVERAGE('Monthly P&L'!B9:D9) -> 17424.138
A11: Avg Monthly Revenue (M10-12) | B11: =AVERAGE('Monthly P&L'!K9:M9) -> 28211.321
A12: Month 12 Net Income | B12: ='Monthly P&L'!M35 -> -4146.3209

Sheet Unit Economics
A1: ROAST LAUNCH
A2: UNIT ECONOMICS ANALYSIS
A4: Item | B4: Unit Price | C4: COGS | D4: Margin $ | E4: Margin %
A5: ESPRESSO-BASED DRINKS
A6: Espresso (Single) | B6: 2.5 | C6: 0.4 | D6: =B6-C6 -> 2.1 | E6: =D6/B6 -> 0.84
A7: Americano (12oz) | B7: 3 | C7: 0.5 | D7: =B7-C7 -> 2.5 | E7: =D7/B7 -> 0.83333333
A8: Latte (12oz) | B8: 4.5 | C8: 1.2 | D8: =B8-C8 -> 3.3 | E8: =D8/B8 -> 0.73333333
A9: Cappuccino (12oz) | B9: 4.5 | C9: 1.2 | D9: =B9-C9 -> 3.3 | E9: =D9/B9 -> 0.73333333
A10: Macchiato (12oz) | B10: 4.25 | C10: 1.1 | D10: =B10-C10 -> 3.15 | E10: =D10/B10 -> 0.74117647
A11: Flat White (12oz) | B11: 5 | C11: 1.4 | D11: =B11-C11 -> 3.6 | E11: =D11/B11 -> 0.72
A13: DRIP & BATCH BREW
A14: Drip Coffee (12oz) | B14: 2.75 | C14: 0.35 | D14: =B14-C14 -> 2.4 | E14: =D14/B14 -> 0.87272727
A15: Drip Coffee (16oz) | B15: 3.25 | C15: 0.42 | D15: =B15-C15 -> 2.83 | E15: =D15/B15 -> 0.87076923
A16: Cold Brew | B16: 3.5 | C16: 0.5 | D16: =B16-C16 -> 3 | E16: =D16/B16 -> 0.85714286
A18: FOOD & PASTRIES
A19: Pastry/Croissant | B19: 4.5 | C19: 1.5 | D19: =B19-C19 -> 3 | E19: =D19/B19 -> 0.66666667
A20: Muffin/Scone | B20: 3.75 | C20: 1.25 | D20: =B20-C20 -> 2.5 | E20: =D20/B20 -> 0.66666667
A21: Sandwich | B21: 8.5 | C21: 3 | D21: =B21-C21 -> 5.5 | E21: =D21/B21 -> 0.64705882
A22: Acai Bowl | B22: 7.5 | C22: 2.5 | D22: =B22-C22 -> 5 | E22: =D22/B22 -> 0.66666667

Sheet Break-Even Analysis
A1: ROAST LAUNCH
A2: BREAK-EVEN ANALYSIS
A4: KEY ASSUMPTIONS
A5: Fixed Operating Expenses | B5: =Assumptions!B20+Assumptions!B21+(Assumptions!B22*(1+Assumptions!B23))+Assumptions!B24+Assumptions!B25+Assumptions!B26+Assumptions!B27+Assumptions!B28+Assumptions!B29 -> 21095 | C5: Total fixed costs per month
A6: Variable COGS % of Revenue | B6: =Assumptions!B14+Assumptions!B15+Assumptions!B16+Assumptions!B17 -> 0.43 | C6: Total COGS costs
A7: Contribution Margin % | B7: =1-B6 -> 0.57 | C7: Remaining after variable costs
A8: Average Ticket Price | B8: =Assumptions!B10 -> 7.5 | C8: Average customer spend
A10: BREAK-EVEN CALCULATIONS
A11: Break-Even Monthly Revenue | B11: =B5/B7 -> 37008.772 | C11: Revenue to reach break-even
A12: Break-Even Daily Customers | B12: =(B5/B7)/(B8*Assumptions!B11) -> 224.29559 | C12: Customers needed per day
A13: Break-Even Month (Year 1) | B13: =IFERROR(MATCH(TRUE(), 'Monthly P&L'!B35:M35>0, 0), "Not yet") -> Not yet | C13: First profitable month

Sheet Cash Flow
A1: ROAST LAUNCH
A2: 24-MONTH CASH FLOW PROJECTION
A3: MONTH | B3: M1 | C3: M2 | D3: M3 | E3: M4 | F3: M5 | G3: M6 | H3: M7 | I3: M8 | J3: M9 | K3: M10 | L3: M11 | M3: M12 | N3: Y2M1 | O3: Y2M2 | P3: Y2M3 | Q3: Y2M4 | R3: Y2M5 | S3: Y2M6 | T3: Y2M7 | U3: Y2M8 | V3: Y2M9 | W3: Y2M10 | X3: Y2M11 | Y3: Y2M12
A4: OPENING CASH BALANCE | B4: ='Startup Costs'!B47 -> 25000 | C4: =B14 -> 20405 | D4: =C14 -> 37812.5 | E4: =D14 -> 56177.412 | F4: =E14 -> 75552.395 | G4: =F14 -> 95993.002 | H4: =G14 -> 117557.84 | I4: =H14 -> 140308.75 | J4: =I14 -> 164310.95 | ... Y4: =X14 -> 664047.95
A6: CASH INFLOWS
A7: Operating Revenue | B7: ='Monthly P&L'!B9 -> 16500 | C7: ='Monthly P&L'!C9 -> 17407.5 | D7: ='Monthly P&L'!D9 -> 18364.912 | E7: ='Monthly P&L'!E9 -> 19374.983 | F7: ='Monthly P&L'!F9 -> 20440.607 | G7: ='Monthly P&L'!G9 -> 21564.84 | H7: ='Monthly P&L'!H9 -> 22750.906 | I7: ='Monthly P&L'!I9 -> 24002.206 | ... Y7: ='Monthly P&L'!Y9 -> 36300
A9: CASH OUTFLOWS
A10: Operating Expenses | B10: ='Monthly P&L'!B30 -> 21095 | C10: ='Monthly P&L'!C33 -> 0 | D10: ='Monthly P&L'!D33 -> 0 | E10: ='Monthly P&L'!E33 -> 0 | F10: ='Monthly P&L'!F33 -> 0 | G10: ='Monthly P&L'!G33 -> 0 | H10: ='Monthly P&L'!H33 -> 0 | I10: ='Monthly P&L'!I33 -> 0 | J10: ='Monthly P&L'!J33 -> 0 | ... Y10: ='Monthly P&L'!Y33 -> 0
A11: Income Taxes | B11: ='Monthly P&L'!B33 -> 0 | C11: ='Monthly P&L'!C34 -> 0 | D11: ='Monthly P&L'!D34 -> 0 | E11: ='Monthly P&L'!E34 -> 0 | F11: ='Monthly P&L'!F34 -> 0 | G11: ='Monthly P&L'!G34 -> 0 | H11: ='Monthly P&L'!H34 -> 0 | I11: ='Monthly P&L'!I34 -> 0 | J11: ='Monthly P&L'!J34 -> 0 | ... Y11: ='Monthly P&L'!Y34 -> 0
A13: NET MONTHLY CASH FLOW | B13: =B7-B10-B11 -> -4595 | C13: =C7-C10-C11 -> 17407.5 | D13: =D7-D10-D11 -> 18364.912 | E13: =E7-E10-E11 -> 19374.983 | F13: =F7-F10-F11 -> 20440.607 | G13: =G7-G10-G11 -> 21564.84 | H13: =H7-H10-H11 -> 22750.906 | I13: =I7-I10-I11 -> 24002.206 | ... Y13: =Y7-Y10-Y11 -> 36300
A14: CLOSING CASH BALANCE | B14: =B4+B13 -> 20405 | C14: =C4+C13 -> 37812.5 | D14: =D4+D13 -> 56177.412 | E14: =E4+E13 -> 75552.395 | F14: =F4+F13 -> 95993.002 | G14: =G4+G13 -> 117557.84 | H14: =H4+H13 -> 140308.75 | I14: =I4+I13 -> 164310.95 | ... Y14: =Y4+Y13 -> 700347.95
A16: Cash Burn Warning | B16: =IF(B14<0, "⚠", "") | C16: =IF(C14<0, "⚠", "") | D16: =IF(D14<0, "⚠", "") | E16: =IF(E14<0, "⚠", "") | F16: =IF(F14<0, "⚠", "") | G16: =IF(G14<0, "⚠", "") | H16: =IF(H14<0, "⚠", "") | I16: =IF(I14<0, "⚠", "") | ... Y16: =IF(Y14<0, "⚠", "")

Sheet Scenario Analysis
A1: ROAST LAUNCH
A2: SCENARIO ANALYSIS - 3 CASE PROJECTIONS
A4: SCENARIO ASSUMPTIONS
A5: Parameter | B5: Conservative | C5: Base Case | D5: Optimistic
A6: Customer Growth Rate | B6: 0.035 | C6: 0.055 | D6: 0.08
A7: Revenue Volume Multiplier | B7: 0.7 | C7: 1 | D7: 1.3
A8: COGS % of Revenue | B8: 0.5 | C8: 0.43 | D8: 0.4
A9: Operating Expense Multiplier | B9: 1.1 | C9: 1 | D9: 0.95
A10: Starting Daily Customers | B10: 70 | C10: 100 | D10: 130
A13: KEY METRICS COMPARISON
A14: Metric | B14: Conservative | C14: Base Case | D14: Optimistic
A15: Year 1 Revenue | B15: Lower volume | C15: Realistic base case | D15: Strong growth
A16: Year 1 Net Income | B16: Longer path to profit | C16: Month 8-10 target | D16: Faster growth
A17: Months to Profitability | B17: Extended timeline | C17: 8-10 months | D17: Earlier breakeven
A18: Year 2 Net Income | B18: Moderate profitability | C18: Healthy growth | D18: Strong profitability
A19: Capital Needed | B19: Minimal buffer | C19: +3 months reserve | D19: Less capital needed
A22: SCENARIO INTERPRETATION
A23: CONSERVATIVE
A24: Lower customer adoption, higher costs. Still reaches profitability but extends timeline.
A25: BASE CASE
A26: Realistic assumptions based on industry benchmarks. Shows profitability by Month 8-10.
A27: OPTIMISTIC
A28: Strong execution and customer growth. Fast path to profitability with efficient operations.
