Workbook

Sheet Quick Start
A1: ROAST LAUNCH
A2: Location Profitability Scorecard
A4: How to Use This Tool in 30 Minutes
A6: Step 1: Enter Your Top 3 Locations
A7: Go to the 'Dashboard' sheet and enter the names of up to 3 locations you're considering. Then, open each location's assessment sheet (Location 1 Assessment, Location 2 Assessment, Location 3 Assessment).
A9: Step 2: Score Each Location on Key Criteria
A10: For each location, evaluate the 6 scoring categories: • Foot Traffic & Visibility (25 points) - foot traffic, visibility, signage, anchor proximity • Demographics & Market (20 points) - population, income, age, education, growth • Competition Analysis (15 points) - competitor count, distance, differentiation • Rent & Financials (20 points) - rent, costs, ratios, lease terms • Accessibility & Parking (10 points) - parking, transit, bike-friendly, ADA • Space & Layout (10 points) - sqft, kitchen, seating, outdoor space, storage Score each criterion from 1-10 (1=weak, 10=strong). Add notes to explain your scoring.
A23: Step 3: Compare Results on Dashboard
A24: Return to the 'Dashboard' sheet. You'll see side-by-side scores for all 3 locations with category breakdowns and a clear recommendation.
A26: Tips for Success
A27: • Visit each location at different times (morning, lunch, evening) to assess foot traffic • Use Google Maps to research demographics, nearby competitors, and transit access • Be honest with your scoring - this tool is only as good as your data • Refer to the 'Scoring Guide' sheet if you're unsure about any criterion • All scores are weighted - Foot Traffic and Financials have the most impact on final score

Sheet Dashboard
A1: ROAST LAUNCH - Scorecard Dashboard
A3: Enter location names below, then complete each location's assessment sheet.
A5: Location Name
A7: OVERALL SCORES
A8: Metric | B8: Location 1 | C8: Location 2 | D8: Location 3
A9: Final Score (out of 10) | B9: ='Location 1 Assessment'!B59 -> 7.9 | C9: ='Location 2 Assessment'!B59 | D9: ='Location 3 Assessment'!B59
A10: Foot Traffic & Visibility (25%) | B10: ='Location 1 Assessment'!B11 -> 8.2 | C10: ='Location 2 Assessment'!B11 | D10: ='Location 3 Assessment'!B11
A11: Demographics & Market (20%) | B11: ='Location 1 Assessment'!B20 -> 8 | C11: ='Location 2 Assessment'!B20 | D11: ='Location 3 Assessment'!B20
A12: Competition Analysis (15%) | B12: ='Location 1 Assessment'!B29 -> 7.6 | C12: ='Location 2 Assessment'!B29 | D12: ='Location 3 Assessment'!B29
A13: Rent & Financials (20%) | B13: ='Location 1 Assessment'!B38 -> 7.8 | C13: ='Location 2 Assessment'!B38 | D13: ='Location 3 Assessment'!B38
A14: Accessibility & Parking (10%) | B14: ='Location 1 Assessment'!B47 -> 8.2 | C14: ='Location 2 Assessment'!B47 | D14: ='Location 3 Assessment'!B47
A15: Space & Layout (10%) | B15: ='Location 1 Assessment'!B56 -> 7.6 | C15: ='Location 2 Assessment'!B56 | D15: ='Location 3 Assessment'!B56
A16: RECOMMENDATION
A17: Score 7-10: STRONG - Excellent market fit. Recommend pursuing this location. Score 4-6: FAIR - Viable option with some concerns. Review specific category scores to understand weaknesses. Score 1-3: WEAK - Significant concerns. Recommend reconsidering this location.

Sheet Location 1 Assessment
A1: ROAST LAUNCH - Location 1 Assessment
A2: Enter location name: | B2: Downtown Main Street
A4: 1. FOOT TRAFFIC & VISIBILITY (25% of score)
A5: Criterion | B5: Score (1-10) | C5: Notes
A6: Daily pedestrian count (estimate) | B6: 9 | C6: ~800 pedestrians daily, strong lunch crowd
A7: Vehicle traffic/road visibility | B7: 8 | C7: High volume on main street, near shopping center
A8: Storefront visibility from street | B8: 8 | C8: Corner storefront, high visibility
A9: Signage opportunities/visibility | B9: 9 | C9: Large windows, excellent signage potential
A10: Proximity to anchor tenants/generators | B10: 7 | C10: Adjacent to shopping mall and office complex
A11: CATEGORY AVERAGE (25%) | B11: =IFERROR(AVERAGE(B6:B10),"") -> 8.2
A13: 2. DEMOGRAPHICS & MARKET (20% of score)
A14: Criterion | B14: Score (1-10) | C14: Notes
A15: Population density within 1 mile | B15: 8 | C15: High density urban area, 15,000+ people per sq mi
A16: Median household income level | B16: 8 | C16: $85,000+ median household income
A17: Age distribution (target: 25-45) | B17: 9 | C17: Strong 25-45 age demographic, professionals
A18: Education level/affluence | B18: 8 | C18: College educated population, affluent
A19: Population growth trends | B19: 7 | C19: Downtown area growing, new development coming
A20: CATEGORY AVERAGE (20%) | B20: =IFERROR(AVERAGE(B15:B19),"") -> 8
A22: 3. COMPETITION ANALYSIS (15% of score)
A23: Criterion | B23: Score (1-10) | C23: Notes
A24: Number of specialty coffee shops within 1 mile | B24: 8 | C24: Only 1 specialty coffee shop within 1 mile
A25: Distance to nearest competitor | B25: 8 | C25: Nearest competitor ~0.4 miles away
A26: Competitor quality/positioning | B26: 7 | C26: Competitor is mid-market, opportunity for premium positioning
A27: Market saturation assessment | B27: 7 | C27: Good market size but not saturated
A28: Differentiation opportunity | B28: 8 | C28: Can differentiate with quality and unique offerings
A29: CATEGORY AVERAGE (15%) | B29: =IFERROR(AVERAGE(B24:B28),"") -> 7.6
A31: 4. RENT & FINANCIALS (20% of score)
A32: Criterion | B32: Score (1-10) | C32: Notes
A33: Monthly rent per sq ft | B33: 8 | C33: $18/sqft/year, reasonable for downtown
A34: Total monthly rent affordability | B34: 8 | C34: $3,600/month for 2,400 sqft
A35: Rent-to-revenue ratio estimate | B35: 8 | C35: Estimated $40k/month revenue, rent = 9% of revenue
A36: Build-out/improvement costs | B36: 7 | C36: $60k build-out estimated, manageable
A37: Lease terms favorability | B37: 8 | C37: 5-year lease, 3% annual escalation, favorable terms
A38: CATEGORY AVERAGE (20%) | B38: =IFERROR(AVERAGE(B33:B37),"") -> 7.8
A40: 5. ACCESSIBILITY & PARKING (10% of score)
A41: Criterion | B41: Score (1-10) | C41: Notes
A42: Street parking availability | B42: 7 | C42: Street parking available, 2-hour limit peak hours
A43: Lot/garage parking proximity | B43: 8 | C43: Public lot nearby with 300+ spaces
A44: Public transit access | B44: 9 | C44: Bus transit hub 2 blocks away, multiple lines
A45: Bike-friendly infrastructure | B45: 8 | C45: Bike lanes on main street, bike parking available
...

Sheet Location 2 Assessment
A1: ROAST LAUNCH - Location 2 Assessment
A2: Enter location name:
A4: 1. FOOT TRAFFIC & VISIBILITY (25% of score)
A5: Criterion | B5: Score (1-10) | C5: Notes
A6: Daily pedestrian count (estimate)
A7: Vehicle traffic/road visibility
A8: Storefront visibility from street
A9: Signage opportunities/visibility
A10: Proximity to anchor tenants/generators
A11: CATEGORY AVERAGE (25%) | B11: =IFERROR(AVERAGE(B6:B10),"")
A13: 2. DEMOGRAPHICS & MARKET (20% of score)
A14: Criterion | B14: Score (1-10) | C14: Notes
A15: Population density within 1 mile
A16: Median household income level
A17: Age distribution (target: 25-45)
A18: Education level/affluence
A19: Population growth trends
A20: CATEGORY AVERAGE (20%) | B20: =IFERROR(AVERAGE(B15:B19),"")
A22: 3. COMPETITION ANALYSIS (15% of score)
A23: Criterion | B23: Score (1-10) | C23: Notes
A24: Number of specialty coffee shops within 1 mile
A25: Distance to nearest competitor
A26: Competitor quality/positioning
A27: Market saturation assessment
A28: Differentiation opportunity
A29: CATEGORY AVERAGE (15%) | B29: =IFERROR(AVERAGE(B24:B28),"")
A31: 4. RENT & FINANCIALS (20% of score)
A32: Criterion | B32: Score (1-10) | C32: Notes
A33: Monthly rent per sq ft
A34: Total monthly rent affordability
A35: Rent-to-revenue ratio estimate
A36: Build-out/improvement costs
A37: Lease terms favorability
A38: CATEGORY AVERAGE (20%) | B38: =IFERROR(AVERAGE(B33:B37),"")
A40: 5. ACCESSIBILITY & PARKING (10% of score)
A41: Criterion | B41: Score (1-10) | C41: Notes
A42: Street parking availability
A43: Lot/garage parking proximity
A44: Public transit access
A45: Bike-friendly infrastructure
...

Sheet Location 3 Assessment
A1: ROAST LAUNCH - Location 3 Assessment
A2: Enter location name:
A4: 1. FOOT TRAFFIC & VISIBILITY (25% of score)
A5: Criterion | B5: Score (1-10) | C5: Notes
A6: Daily pedestrian count (estimate)
A7: Vehicle traffic/road visibility
A8: Storefront visibility from street
A9: Signage opportunities/visibility
A10: Proximity to anchor tenants/generators
A11: CATEGORY AVERAGE (25%) | B11: =IFERROR(AVERAGE(B6:B10),"")
A13: 2. DEMOGRAPHICS & MARKET (20% of score)
A14: Criterion | B14: Score (1-10) | C14: Notes
A15: Population density within 1 mile
A16: Median household income level
A17: Age distribution (target: 25-45)
A18: Education level/affluence
A19: Population growth trends
A20: CATEGORY AVERAGE (20%) | B20: =IFERROR(AVERAGE(B15:B19),"")
A22: 3. COMPETITION ANALYSIS (15% of score)
A23: Criterion | B23: Score (1-10) | C23: Notes
A24: Number of specialty coffee shops within 1 mile
A25: Distance to nearest competitor
A26: Competitor quality/positioning
A27: Market saturation assessment
A28: Differentiation opportunity
A29: CATEGORY AVERAGE (15%) | B29: =IFERROR(AVERAGE(B24:B28),"")
A31: 4. RENT & FINANCIALS (20% of score)
A32: Criterion | B32: Score (1-10) | C32: Notes
A33: Monthly rent per sq ft
A34: Total monthly rent affordability
A35: Rent-to-revenue ratio estimate
A36: Build-out/improvement costs
A37: Lease terms favorability
A38: CATEGORY AVERAGE (20%) | B38: =IFERROR(AVERAGE(B33:B37),"")
A40: 5. ACCESSIBILITY & PARKING (10% of score)
A41: Criterion | B41: Score (1-10) | C41: Notes
A42: Street parking availability
A43: Lot/garage parking proximity
A44: Public transit access
A45: Bike-friendly infrastructure
...

Sheet Scoring Guide
A1: ROAST LAUNCH - Scoring Guide
A3: Use this guide to score each criterion on a scale of 1-10. Higher scores indicate stronger fit for a successful location.
A5: FOOT TRAFFIC & VISIBILITY
A6: Score 1 | B6: Weak | C6: Very low foot traffic (<100/day); poor visibility; no peak hours; limited nearby generators
A7: Score 4 | B7: Fair | C7: Moderate foot traffic (100-300/day); adequate visibility; some peak hours; few traffic generators
A8: Score 7 | B8: Strong | C8: High foot traffic (300+/day); excellent visibility; clear peak hours; multiple traffic generators (transit, shopping, offices)
A10: DEMOGRAPHICS & MARKET
A11: Score 1 | B11: Weak | C11: Poor market fit; low income; mismatched age groups; weak coffee culture
A12: Score 4 | B12: Fair | C12: Partial fit; moderate income; some target age groups (25-45); growing interest in specialty coffee
A13: Score 7 | B13: Strong | C13: Excellent fit; high income; strong target age groups; affluent/educated population; established coffee culture
A15: COMPETITION ANALYSIS
A16: Score 1 | B16: Weak | C16: Multiple specialty coffee shops within 1 mile; very limited differentiation; saturated market
A17: Score 4 | B17: Fair | C17: 2-3 competitors within 1 mile; some differentiation possible; moderate competition
A18: Score 7 | B18: Strong | C18: 0-1 competitors within 1 mile; strong differentiation opportunity; underserved market
A20: RENT & FINANCIALS
A21: Score 1 | B21: Weak | C21: Rent >20% of estimated revenue; high build-out costs; unfavorable lease terms
A22: Score 4 | B22: Fair | C22: Rent 10-15% of revenue; moderate build-out costs; standard lease terms
A23: Score 7 | B23: Strong | C23: Rent <10% of revenue; low build-out costs; favorable lease terms; strong financials
A25: ACCESSIBILITY & PARKING
A26: Score 1 | B26: Weak | C26: Poor parking; no transit access; limited accessibility; ADA concerns
A27: Score 4 | B27: Fair | C27: Adequate parking; basic transit; acceptable accessibility
A28: Score 7 | B28: Strong | C28: Ample parking; excellent transit; fully ADA compliant; bike-friendly
A30: SPACE & LAYOUT
A31: Score 1 | B31: Weak | C31: Too small or poorly configured; inadequate kitchen; limited seating; no storage
A32: Score 4 | B32: Fair | C32: Adequate size; acceptable kitchen; reasonable seating capacity; basic storage
A33: Score 7 | B33: Strong | C33: Ideal size; well-designed kitchen; good seating; ample storage; outdoor potential
